Workbook

Sheet Read me
A1: Agentic SDLC: execution plan and tracker
A2: v1 draft · Fri 23 Oct 2026 · for the biweekly review on Mon 26 Oct 2026 · owner: Amar Kumar (transformation lead)
A4: What this is | B4: The execution plan for the Agentic SDLC program: major areas, actions with sub-steps, measurable outputs, current status, dates, owners and the support each action needs. The plan page (index.html) explains the why; this file tracks the how and when.
A5: Sheets | B5: Summary: status by area. Plan: the tracker. Timeline: weekly view built from the Plan dates. KPIs: baselines and targets. Milestones: key dates and autonomy stages. Decisions: what we need from leadership. Task force: roles. Agent framework: the agents and what they merge. Risks. Evidence: industry practice with sources.
A6: Weekly update | B6: Every Friday by 17:00 the action owner updates Plan columns F (current status), G (status) and H (RAG). Dates change only with a decision at the biweekly review; note the reason in Remarks. IDs never change.
A7: Status values | B7: Not started · In progress · Ongoing · Done · Blocked.
A8: RAG | B8: Green: on track. Amber: at risk; the recovery step is in Remarks. Red: will miss its date without a decision; raise it at the next review.
A9: Cell colours | B9: Yellow fill: still to fill in (names, baselines). Blue numbers on the KPIs sheet: targets you can change. Black numbers: formulas; do not type over them. Green numbers: links to another sheet.
A10: Sources | B10: Targets 27/48 → 40/48 repos by November → 48/48 by January, the 1.3x multiple against a 10x aspiration, the single pilot team, the agent framework from December and the autonomy stages come from the company strategy document as discussed on the call with the program sponsor on Fri 23 Oct 2026. Everything else marked 'Proposed' is a recommendation to confirm on Mon 26 Oct.
A11: Assumptions | B11: Biweekly reviews with the executive sponsor every other Monday from Mon 26 Oct 2026. Task force in place by Mon 2 Nov 2026. Low capacity from Mon 21 Dec 2026 to Fri 1 Jan 2027. Diwali week in November may move the Mon 9 Nov review. All weekdays were checked against the calendar.
A12: Related files | B12: In the prd-to-pr-rule-skills repo: docs/adoption/index.html (plan page), docs/adoption/vision.md (source vision), docs/adoption/starter-kit/ (reference hooks, skills, subagents, templates and eval harness), and plugins/ (the standard that ships to every machine).

Sheet Summary
A1: Status by area
A2: Every number on this sheet is a formula over the Plan sheet.
A4: Area | B4: Actions | C4: Done | D4: In progress | E4: Ongoing | F4: Not started | G4: Blocked | H4: Amber | I4: Red | J4: % done | K4: Next open finish date
A5: 1. Program and task force | B5: =COUNTIF(Plan!$B$2:$B$400,$A5) -> 9 | C5: =COUNTIFS(Plan!$B$2:$B$400,$A5,Plan!$G$2:$G$400,"Done") -> 0 | D5: =COUNTIFS(Plan!$B$2:$B$400,$A5,Plan!$G$2:$G$400,"In progress") -> 4 | E5: =COUNTIFS(Plan!$B$2:$B$400,$A5,Plan!$G$2:$G$400,"Ongoing") -> 0 | F5: =COUNTIFS(Plan!$B$2:$B$400,$A5,Plan!$G$2:$G$400,"Not started") -> 5 | G5: =COUNTIFS(Plan!$B$2:$B$400,$A5,Plan!$G$2:$G$400,"Blocked") -> 0 | H5: =COUNTIFS(Plan!$B$2:$B$400,$A5,Plan!$H$2:$H$400,"Amber") -> 2 | I5: =COUNTIFS(Plan!$B$2:$B$400,$A5,Plan!$H$2:$H$400,"Red") -> 0 | J5: =IF($B5=0,"",$C5/$B5) -> 0 | K5: =IF(_xlfn.MINIFS(Plan!$J$2:$J$400,Plan!$B$2:$B$400,$A5,Plan!$G$2:$G$400,"<>Done")=0,"",_xlfn.MINIFS(Plan!$J$2:$J$400,Plan!$B$2:$B$400,$A5,Plan!$G$2:$G$400,"<>Done")) -> 46321
A6: 2. Measurement and baseline | B6: =COUNTIF(Plan!$B$2:$B$400,$A6) -> 8 | C6: =COUNTIFS(Plan!$B$2:$B$400,$A6,Plan!$G$2:$G$400,"Done") -> 0 | D6: =COUNTIFS(Plan!$B$2:$B$400,$A6,Plan!$G$2:$G$400,"In progress") -> 0 | E6: =COUNTIFS(Plan!$B$2:$B$400,$A6,Plan!$G$2:$G$400,"Ongoing") -> 0 | F6: =COUNTIFS(Plan!$B$2:$B$400,$A6,Plan!$G$2:$G$400,"Not started") -> 8 | G6: =COUNTIFS(Plan!$B$2:$B$400,$A6,Plan!$G$2:$G$400,"Blocked") -> 0 | H6: =COUNTIFS(Plan!$B$2:$B$400,$A6,Plan!$H$2:$H$400,"Amber") -> 2 | I6: =COUNTIFS(Plan!$B$2:$B$400,$A6,Plan!$H$2:$H$400,"Red") -> 0 | J6: =IF($B6=0,"",$C6/$B6) -> 0 | K6: =IF(_xlfn.MINIFS(Plan!$J$2:$J$400,Plan!$B$2:$B$400,$A6,Plan!$G$2:$G$400,"<>Done")=0,"",_xlfn.MINIFS(Plan!$J$2:$J$400,Plan!$B$2:$B$400,$A6,Plan!$G$2:$G$400,"<>Done")) -> 46332
A7: 3. Standardize repositories | B7: =COUNTIF(Plan!$B$2:$B$400,$A7) -> 7 | C7: =COUNTIFS(Plan!$B$2:$B$400,$A7,Plan!$G$2:$G$400,"Done") -> 0 | D7: =COUNTIFS(Plan!$B$2:$B$400,$A7,Plan!$G$2:$G$400,"In progress") -> 1 | E7: =COUNTIFS(Plan!$B$2:$B$400,$A7,Plan!$G$2:$G$400,"Ongoing") -> 0 | F7: =COUNTIFS(Plan!$B$2:$B$400,$A7,Plan!$G$2:$G$400,"Not started") -> 6 | G7: =COUNTIFS(Plan!$B$2:$B$400,$A7,Plan!$G$2:$G$400,"Blocked") -> 0 | H7: =COUNTIFS(Plan!$B$2:$B$400,$A7,Plan!$H$2:$H$400,"Amber") -> 1 | I7: =COUNTIFS(Plan!$B$2:$B$400,$A7,Plan!$H$2:$H$400,"Red") -> 0 | J7: =IF($B7=0,"",$C7/$B7) -> 0 | K7: =IF(_xlfn.MINIFS(Plan!$J$2:$J$400,Plan!$B$2:$B$400,$A7,Plan!$G$2:$G$400,"<>Done")=0,"",_xlfn.MINIFS(Plan!$J$2:$J$400,Plan!$B$2:$B$400,$A7,Plan!$G$2:$G$400,"<>Done")) -> 46332
A8: 4. Agent framework | B8: =COUNTIF(Plan!$B$2:$B$400,$A8) -> 8 | C8: =COUNTIFS(Plan!$B$2:$B$400,$A8,Plan!$G$2:$G$400,"Done") -> 0 | D8: =COUNTIFS(Plan!$B$2:$B$400,$A8,Plan!$G$2:$G$400,"In progress") -> 2 | E8: =COUNTIFS(Plan!$B$2:$B$400,$A8,Plan!$G$2:$G$400,"Ongoing") -> 0 | F8: =COUNTIFS(Plan!$B$2:$B$400,$A8,Plan!$G$2:$G$400,"Not started") -> 6 | G8: =COUNTIFS(Plan!$B$2:$B$400,$A8,Plan!$G$2:$G$400,"Blocked") -> 0 | H8: =COUNTIFS(Plan!$B$2:$B$400,$A8,Plan!$H$2:$H$400,"Amber") -> 0 | I8: =COUNTIFS(Plan!$B$2:$B$400,$A8,Plan!$H$2:$H$400,"Red") -> 0 | J8: =IF($B8=0,"",$C8/$B8) -> 0 | K8: =IF(_xlfn.MINIFS(Plan!$J$2:$J$400,Plan!$B$2:$B$400,$A8,Plan!$G$2:$G$400,"<>Done")=0,"",_xlfn.MINIFS(Plan!$J$2:$J$400,Plan!$B$2:$B$400,$A8,Plan!$G$2:$G$400,"<>Done")) -> 46332
A9: 5. Agentic SDLC workflow | B9: =COUNTIF(Plan!$B$2:$B$400,$A9) -> 8 | C9: =COUNTIFS(Plan!$B$2:$B$400,$A9,Plan!$G$2:$G$400,"Done") -> 0 | D9: =COUNTIFS(Plan!$B$2:$B$400,$A9,Plan!$G$2:$G$400,"In progress") -> 0 | E9: =COUNTIFS(Plan!$B$2:$B$400,$A9,Plan!$G$2:$G$400,"Ongoing") -> 0 | F9: =COUNTIFS(Plan!$B$2:$B$400,$A9,Plan!$G$2:$G$400,"Not started") -> 8 | G9: =COUNTIFS(Plan!$B$2:$B$400,$A9,Plan!$G$2:$G$400,"Blocked") -> 0 | H9: =COUNTIFS(Plan!$B$2:$B$400,$A9,Plan!$H$2:$H$400,"Amber") -> 0 | I9: =COUNTIFS(Plan!$B$2:$B$400,$A9,Plan!$H$2:$H$400,"Red") -> 0 | J9: =IF($B9=0,"",$C9/$B9) -> 0 | K9: =IF(_xlfn.MINIFS(Plan!$J$2:$J$400,Plan!$B$2:$B$400,$A9,Plan!$G$2:$G$400,"<>Done")=0,"",_xlfn.MINIFS(Plan!$J$2:$J$400,Plan!$B$2:$B$400,$A9,Plan!$G$2:$G$400,"<>Done")) -> 46332
A10: 6. Product builder | B10: =COUNTIF(Plan!$B$2:$B$400,$A10) -> 5 | C10: =COUNTIFS(Plan!$B$2:$B$400,$A10,Plan!$G$2:$G$400,"Done") -> 0 | D10: =COUNTIFS(Plan!$B$2:$B$400,$A10,Plan!$G$2:$G$400,"In progress") -> 0 | E10: =COUNTIFS(Plan!$B$2:$B$400,$A10,Plan!$G$2:$G$400,"Ongoing") -> 0 | F10: =COUNTIFS(Plan!$B$2:$B$400,$A10,Plan!$G$2:$G$400,"Not started") -> 5 | G10: =COUNTIFS(Plan!$B$2:$B$400,$A10,Plan!$G$2:$G$400,"Blocked") -> 0 | H10: =COUNTIFS(Plan!$B$2:$B$400,$A10,Plan!$H$2:$H$400,"Amber") -> 0 | I10: =COUNTIFS(Plan!$B$2:$B$400,$A10,Plan!$H$2:$H$400,"Red") -> 0 | J10: =IF($B10=0,"",$C10/$B10) -> 0 | K10: =IF(_xlfn.MINIFS(Plan!$J$2:$J$400,Plan!$B$2:$B$400,$A10,Plan!$G$2:$G$400,"<>Done")=0,"",_xlfn.MINIFS(Plan!$J$2:$J$400,Plan!$B$2:$B$400,$A10,Plan!$G$2:$G$400,"<>Done")) -> 46416
A11: 7. Security and operations | B11: =COUNTIF(Plan!$B$2:$B$400,$A11) -> 5 | C11: =COUNTIFS(Plan!$B$2:$B$400,$A11,Plan!$G$2:$G$400,"Done") -> 0 | D11: =COUNTIFS(Plan!$B$2:$B$400,$A11,Plan!$G$2:$G$400,"In progress") -> 0 | E11: =COUNTIFS(Plan!$B$2:$B$400,$A11,Plan!$G$2:$G$400,"Ongoing") -> 0 | F11: =COUNTIFS(Plan!$B$2:$B$400,$A11,Plan!$G$2:$G$400,"Not started") -> 5 | G11: =COUNTIFS(Plan!$B$2:$B$400,$A11,Plan!$G$2:$G$400,"Blocked") -> 0 | H11: =COUNTIFS(Plan!$B$2:$B$400,$A11,Plan!$H$2:$H$400,"Amber") -> 1 | I11: =COUNTIFS(Plan!$B$2:$B$400,$A11,Plan!$H$2:$H$400,"Red") -> 0 | J11: =IF($B11=0,"",$C11/$B11) -> 0 | K11: =IF(_xlfn.MINIFS(Plan!$J$2:$J$400,Plan!$B$2:$B$400,$A11,Plan!$G$2:$G$400,"<>Done")=0,"",_xlfn.MINIFS(Plan!$J$2:$J$400,Plan!$B$2:$B$400,$A11,Plan!$G$2:$G$400,"<>Done")) -> 46353
A12: 8. Scale and ROI | B12: =COUNTIF(Plan!$B$2:$B$400,$A12) -> 4 | C12: =COUNTIFS(Plan!$B$2:$B$400,$A12,Plan!$G$2:$G$400,"Done") -> 0 | D12: =COUNTIFS(Plan!$B$2:$B$400,$A12,Plan!$G$2:$G$400,"In progress") -> 0 | E12: =COUNTIFS(Plan!$B$2:$B$400,$A12,Plan!$G$2:$G$400,"Ongoing") -> 0 | F12: =COUNTIFS(Plan!$B$2:$B$400,$A12,Plan!$G$2:$G$400,"Not started") -> 4 | G12: =COUNTIFS(Plan!$B$2:$B$400,$A12,Plan!$G$2:$G$400,"Blocked") -> 0 | H12: =COUNTIFS(Plan!$B$2:$B$400,$A12,Plan!$H$2:$H$400,"Amber") -> 0 | I12: =COUNTIFS(Plan!$B$2:$B$400,$A12,Plan!$H$2:$H$400,"Red") -> 0 | J12: =IF($B12=0,"",$C12/$B12) -> 0 | K12: =IF(_xlfn.MINIFS(Plan!$J$2:$J$400,Plan!$B$2:$B$400,$A12,Plan!$G$2:$G$400,"<>Done")=0,"",_xlfn.MINIFS(Plan!$J$2:$J$400,Plan!$B$2:$B$400,$A12,Plan!$G$2:$G$400,"<>Done")) -> 46626
A13: All areas | B13: =SUM(B5:B12) -> 54 | C13: =SUM(C5:C12) -> 0 | D13: =SUM(D5:D12) -> 7 | E13: =SUM(E5:E12) -> 0 | F13: =SUM(F5:F12) -> 47 | G13: =SUM(G5:G12) -> 0 | H13: =SUM(H5:H12) -> 6 | I13: =SUM(I5:I12) -> 0 | J13: =IF($B13=0,"",$C13/$B13) -> 0 | K13: =IF(_xlfn.MINIFS(Plan!$J$2:$J$400,Plan!$G$2:$G$400,"<>Done")=0,"",_xlfn.MINIFS(Plan!$J$2:$J$400,Plan!$G$2:$G$400,"<>Done")) -> 46321
A15: This week
A16: Open actions due in the next 14 days | B16: =COUNTIFS(Plan!$J$2:$J$400,">="&TODAY(),Plan!$J$2:$J$400,"<="&TODAY()+14,Plan!$G$2:$G$400,"<>Done") -> 11
A17: Open actions past their finish date | B17: =COUNTIFS(Plan!$J$2:$J$400,"<"&TODAY(),Plan!$G$2:$G$400,"<>Done",Plan!$G$2:$G$400,"<>Ongoing") -> 0
A18: Repos meeting the standard: baseline | B18: =KPIs!$F$6 -> 27
A19: Repos meeting the standard: target Mon 30 Nov 2026 | B19: =KPIs!$G$6 -> 40
A20: Repos meeting the standard: target Fri 29 Jan 2027 | B20: =KPIs!$H$6 -> 48
A21: Next biweekly review | B21: =IF(TODAY()<DATE(2026,10,26),DATE(2026,10,26),DATE(2026,10,26)+14*CEILING((TODAY()-DATE(2026,10,26))/14,1)) -> 46321

Sheet Plan
A1: ID | B1: Area | C1: Action | D1: Sub-steps | E1: Measurable output (done when) | F1: Current status (23 Oct 2026) | G1: Status | H1: RAG | I1: Start | J1: Planned finish | K1: Owner | L1: Support needed | M1: Depends on | N1: Stage | O1: Remarks
A2: 1.1 | B2: 1. Program and task force | C2: Review plan v1 at the biweekly review | D2: Walk through this tracker and the plan page; confirm targets (40/48 repos by 30 Nov, 48/48 by 29 Jan, framework v1 by 18 Dec); take decisions D1–D5; log changes. | E2: Plan v1 accepted, or a dated change list; decisions recorded on the Decisions sheet. | F2: Draft ready Fri 23 Oct; sponsor review over the weekend. | G2: In progress | H2: Green | I2: 46318 | J2: 46321 | K2: Amar (lead) | L2: Sponsor review before Monday; 30 minutes in the executive sponsor's review. | N2: Program | O2: Final version on Monday morning; share the draft earlier if asked.
A3: 1.2 | B3: 1. Program and task force | C3: Form the task force | D3: Agree roles and allocation (Task force sheet); nominations from the engineering people leads; the executive sponsor approves; add members to the 11:00 meeting. | E3: 6–7 named members, at least 50% allocated from Mon 2 Nov 2026 to Fri 29 Jan 2027, approved by the executive sponsor. | F3: People leads agreed to provide people; names not confirmed. | G3: In progress | H3: Amber | I3: 46321 | J3: 46323 | K3: Program sponsor | L3: Nominations: engineering people leads. Approval: executive sponsor. | M3: 1.1 | N3: Program
A4: 1.3 | B4: 1. Program and task force | C4: Kick off the task force | D4: Walk through the plan, the roles, the standard and the starter kit; every member takes first-week actions. | E4: Kickoff held; every member owns at least one action in this tracker. | F4: Not scheduled. | G4: Not started | H4: Green | I4: 46324 | J4: 46324 | K4: Amar (lead) | L4: Task force members. | M4: 1.2 | N4: Program
A5: 1.4 | B5: 1. Program and task force | C5: Run the program cadence | D5: Daily 11:00 task-force stand-up; Friday demo; biweekly review with the executive sponsor; this tracker as the single source of truth, updated every Friday; decision and risk logs. | E5: Cadence running from Thu 29 Oct; tracker updated every Friday by 17:00; every review starts from the tracker. | F5: 11:00 meeting and biweekly review already exist. | G5: Not started | H5: Green | I5: 46324 | J5: 46689 | K5: Amar (lead) | L5: Members join the 11:00 meeting. | M5: 1.3 | N5: Program | O5: Ongoing for the whole program.
A6: 1.5 | B6: 1. Program and task force | C6: Inventory and consolidate existing agent efforts | D6: List every agent, skill, prompt library and bot built across teams, including the security, operations and requirement-analysis agents; record owner, purpose, users and tech; decide merge, keep or retire; invite owners to contribute through the framework. | E6: Inventory with a decision for every item; no new standalone agents outside the framework after Fri 6 Nov. | F6: Several teams have built agents on their own. | G6: Not started | H6: Amber | I6: 46321 | J6: 46332 | K6: Amar (lead) | L6: Team leads share what exists; The executive sponsor backs the one-framework rule (D3). | N6: Program
A7: 1.6 | B7: 1. Program and task force | C7: Lead focus and working arrangement | D7: Pause other work (for example Kompactor) until Fri 29 Jan 2027; spend 2–3 days a week on site with the sponsor during November. | E7: Lead's time fully on this program; on-site days in the calendar. | F7: Agreed in principle on the 23 Oct call. | G7: In progress | H7: Green | I7: 46321 | J7: 46325 | K7: Amar (lead) | L7: Sponsor; executive sponsor informed. | N7: Program | O7: Requested by the executive sponsor.
A8: 1.7 | B8: 1. Program and task force | C8: Industry evidence pack | D8: Condense the company research already in this repo (docs/research.md: 29 sourced cases including Stripe, Spotify, Ramp, Uber and Airbnb) and vendor practice (Anthropic, OpenAI, Google) on skills, plugins and agents into one page with sources. | E8: One-page evidence pack with cited sources, presented at the Mon 9 Nov review. | F8: Research done (docs/research.md, companies page); key facts on the Evidence sheet. | G8: In progress | H8: Green | I8: 46321 | J8: 46332 | K8: Amar (lead) | N8: Program | O8: Use it wherever the plan differs from a stated preference.
A9: 1.8 | B9: 1. Program and task force | C9: Align the strategy document | D9: Answer the open review comments; link this tracker from the path-forward section; keep one set of targets across the document, the plan page and this tracker. | E9: Comments resolved; document, page and tracker show the same targets and dates. | F9: Comments open on the strategy document. | G9: Not started | H9: Green | I9: 46321 | J9: 46323 | K9: Amar (lead) | M9: 1.1 | N9: Program
A10: 1.9 | B10: 1. Program and task force | C10: Engineering-wide communication | D10: Announce the program, the standard and how to contribute; monthly showcase of the multi-agent lifecycle on a real change. | E10: Announcement sent by Fri 6 Nov; first showcase Fri 18 Dec; monthly after that. | F10: Not started. | G10: Not started | H10: Green | I10: 46328 | J10: 46374 | K10: Program sponsor | L10: Lead prepares the content. | M10: 1.1 | N10: Program
A11: 2.1 | B11: 2. Measurement and baseline | C11: Lock the baseline from internal analytics | D11: Pull May–Oct 2026 per team: AI code share, change lead time (requirement to PR), epic lead time, PR throughput and success, defect resolution time, adoption scorecard, the 1.3x multiple; write definitions v1. | E11: Baseline values entered on the KPIs sheet; definitions v1 signed off by the sponsor. | F11: Numbers exist in internal analytics at pod level; definitions not locked. | G11: Not started | H11: Amber | I11: 46321 | J11: 46332 | K11: Measurement analyst (TF) | L11: Access to the analytics dashboards and data (D9). | M11: 1.2 | N11: Measure
A12: 2.2 | B12: 2. Measurement and baseline | C12: Measure AI code share in production | D12: Agree the method: lines in AI-authored commits and PRs merged to main (Claude Code commit attribution plus OpenTelemetry) divided by all merged lines; keep attribution on through managed settings; dashboard by repo, team and month. | E12: Dashboard live with weekly refresh; method written down; baseline recorded. | F12: Named as the top company metric; production-level method not agreed. | G12: Not started | H12: Amber | I12: 46328 | J12: 46346 | K12: Measurement analyst (TF) | L12: Platform team for managed settings; analytics team for the dashboard. | M12: 2.1, 7.2 | N12: Measure
A13: 2.3 | B13: 2. Measurement and baseline | C13: Feature-level flow records for the pilot team | D13: Adopt the feature-record schema (starter kit); join tracker, GitHub, deploy and telemetry data; per feature: request, intent, PR, production, impact. | E13: 100% of the pilot team's features have a record from Tue 1 Dec 2026. | F13: Epic lead time is measured at pod level only. | G13: Not started | H13: Green | I13: 46328 | J13: 46353 | K13: Measurement analyst (TF) | L13: Jira and GitHub admin access. | M13: 2.1 | N13: Measure | O13: Replaces pod-level epic lead time.
A14: 2.4 | B14: 2. Measurement and baseline | C14: Scale feature-level records | D14: Extend the records to each onboarded team; flag whether each change went through the standard workflow. | E14: 4–5 backend teams covered by Fri 29 Jan 2027; all teams by Fri 30 Apr 2027. | F14: Not started. | G14: Not started | H14: Green | I14: 46391 | J14: 46507 | K14: Measurement analyst (TF) | M14: 2.3 | N14: Measure
A15: 2.5 | B15: 2. Measurement and baseline | C15: Claude Code telemetry for every builder | D15: OpenTelemetry export with team tags through managed settings; join to the feature records; cost per team and per change. | E15: At least 90% of sessions tagged by team; cost per successful change reported monthly. | F15: Not confirmed whether telemetry is exported today. | G15: Not started | H15: Green | I15: 46328 | J15: 46339 | K15: Platform/DevEx (TF) | L15: IT for managed settings; observability team for the collector. | M15: 7.2 | N15: Measure
A16: 2.6 | B16: 2. Measurement and baseline | C16: Effort-distribution baseline | D16: Classify the last two quarters of work into feature, defect, maintenance, risk reduction, tech debt and operational support with Claude; audit 40 rows by hand. | E16: Shares per team; audit agreement at least 85%. | F16: Not started. | G16: Not started | H16: Green | I16: 46328 | J16: 46339 | K16: Measurement analyst (TF) | M16: 2.1 | N16: Measure
A17: 2.7 | B17: 2. Measurement and baseline | C17: Monthly gap report and scorecard | D17: 0–10 per pillar with evidence; KPI trend against baseline; RAG per wave; the three decisions leadership needs. Claude drafts, owner reviews. | E17: First report Fri 4 Dec 2026, then the first Friday of each month (Fri 8 Jan in January). | F17: Gap assessment exists in the strategy document. | G17: Not started | H17: Green | I17: 46360 | J17: 46689 | K17: Measurement analyst (TF) | M17: 2.1 | N17: Measure | O17: Ongoing.
A18: 2.8 | B18: 2. Measurement and baseline | C18: Adoption hygiene | D18: Named list of inactive builders with reasons; enablement for each; stop presenting adoption as the growth metric. | E18: At least 95% of builders active weekly, or a named exception. | F18: Adoption is high; exceptions not tracked by name. | G18: Not started | H18: Green | I18: 46328 | J18: 46353 | K18: Platform/DevEx (TF) | L18: Engineering managers. | N18: Stage 1
A19: 3.1 | B19: 3. Standardize repositories | C19: Publish standard v2 | D19: CLAUDE.md template, shared rules, make build/lint/test/verify, known traps, must-not-change rules; review with the 4–5 backend team leads. | E19: Standard v2 published and approved by the backend team leads. | F19: A standard exists; 27 of 48 repos meet it. | G19: In progress | H19: Green | I19: 46321 | J19: 46332 | K19: Amar (lead) | L19: Backend team leads review. | N19: Stage 4
A20: 3.2 | B20: 3. Standardize repositories | C20: Automate the repo scorecard | D20: CI check that scores each repo: CLAUDE.md sections, rules, make targets, guard hooks, frozen-test list, CODEOWNERS on guardrail files; weekly dashboard. | E20: All 48 repos scored automatically every week. | F20: Compliance counted by hand (27/48). | G20: Not started | H20: Green | I20: 46328 | J20: 46339 | K20: Standardization squad (TF) | M20: 3.1 | N20: Stage 4
A21: 3.3 | B21: 3. Standardize repositories | C21: Rollout wave 1: 27 to 40 of 48 repos | D21: Assign the 13 repos to the squad; draft CLAUDE.md with Claude (playbook R1); owning team reviews; merge; scorecard green. | E21: 40 of 48 repos green on the scorecard. | F21: 27 of 48. | G21: Not started | H21: Amber | I21: 46328 | J21: 46356 | K21: Standardization squad (TF) | L21: Each owning team: one review slot of about an hour per repo. | M21: 3.1, 3.2 | N21: Stage 4 | O21: Target from the company plan.
A22: 3.4 | B22: 3. Standardize repositories | C22: Rollout wave 2: 40 to 48 of 48 repos | D22: Same method for the last 8 repos; fix repos that dropped below the standard. | E22: 48 of 48 repos green on the scorecard. | F22: Not started. | G22: Not started | H22: Green | I22: 46357 | J22: 46416 | K22: Standardization squad (TF) | L22: Owning teams review. | M22: 3.3 | N22: Stage 4 | O22: Target from the company plan.
A23: 3.5 | B23: 3. Standardize repositories | C23: Guardrails in every repo | D23: Guard hooks, permission deny rules, frozen-test list and CODEOWNERS from the starter kit; hook self-test in CI; critical repos first. | E23: Critical repos by Fri 18 Dec 2026; all 48 by Fri 29 Jan 2027. | F23: sdlc-core hooks (shell, edit, PR and stop-verify guards) reach every machine through managed settings; the starter kit adds frozen-test and production-boundary guards to fold in. | G23: Not started | H23: Green | I23: 46342 | J23: 46416 | K23: Standardization squad (TF) | L23: Security champion reviews. | M23: 3.1 | N23: Stage 4
A24: 3.6 | B24: 3. Standardize repositories | C24: Policy packs v1 | D24: Security, testing, API and logging/PII packs with rule IDs, drafted from recurring review comments (playbook R4). | E24: Four packs published; reviewer agents cite rule IDs in findings. | F24: Starter security pack exists in the kit. | G24: Not started | H24: Green | I24: 46342 | J24: 46367 | K24: Security champion (TF) | L24: Lead co-writes. | M24: 3.1 | N24: Stage 4
A25: 3.7 | B25: 3. Standardize repositories | C25: Required quality gates on every repo | D25: make verify, the artifact check and the frozen-test check as required CI checks; gate pass rate per repo on the dashboard. | E25: Required on 48 of 48 repos; pass rate visible per repo. | F25: Not started. | G25: Not started | H25: Green | I25: 46391 | J25: 46444 | K25: Standardization squad (TF) | L25: Repo admins for branch protection. | M25: 3.4 | N25: Stage 4
A26: 4.1 | B26: 4. Agent framework | C26: Framework charter | D26: One plugin as the unit of distribution: skills for workflow steps, subagents for specialists, hooks for guardrails, MCP connectors (Jira, GitHub, observability) and evals; naming, versioning, contribution and review rules; agent registry. | E26: Charter approved at the Mon 9 Nov review, including decision D4 (skills-first, packaged as plugins). | F26: This repo already ships the standard as a marketplace: sdlc-core (11 skills, 5 subagents, guard hooks, 5 eval cases), sdlc-connectors and stack plugins, enabled by managed settings. The charter makes it the one framework. | G26: In progress | H26: Green | I26: 46321 | J26: 46332 | K26: Amar (lead) | L26: Executive sponsor decision D4. | M26: 1.5 | N26: Stage 5
A27: 4.2 | B27: 4. Agent framework | C27: Internal plugin marketplace and framework CI | D27: Framework repository; versioned releases; claude plugin validate --strict and the eval self-test as required checks; one-command install for every builder. | E27: Marketplace live; plugin installs in one command; CI blocks broken releases. | F27: In place in this repo: marketplace, managed settings with auto-update, strict validation in CI. Remaining: confirm every builder receives it; make the eval self-test a required check. | G27: In progress | H27: Green | I27: 46335 | J27: 46346 | K27: Framework engineers (TF) | L27: GitHub org admin for the marketplace repository. | M27: 4.1 | N27: Stage 4
A28: 4.3 | B28: 4. Agent framework | C28: Skill-launched UI spike | D28: A skill that renders a change's intent, plan, evidence and review as an HTML page and opens it; decide whether anything richer is needed. | E28: Demo at the Mon 23 Nov review, with a written recommendation. | F28: Not started. | G28: Not started | H28: Green | I28: 46335 | J28: 46346 | K28: Framework engineers (TF) | M28: 4.1 | N28: Stage 5 | O28: Answers the executive sponsor's question on whether skills can launch a UI.
A29: 4.4 | B29: 4. Agent framework | C29: Framework v0.5: plan-and-build agents | D29: Start from sdlc-core's prd-review, spec-write, plan, build and verify skills and its prd-analyst, repo-investigator, builder and qa-verifier agents; merge the existing requirement-analysis agent into prd-review; pilot team uses it daily. | E29: v0.5 released and in daily use by the pilot team. | F29: The skills and agents exist in sdlc-core; the pilot team does not use them daily yet. | G29: Not started | H29: Green | I29: 46335 | J29: 46353 | K29: Framework engineers (TF) | L29: Owner of the requirement-analysis agent. | M29: 4.2 | N29: Stage 5
A30: 4.5 | B30: 4. Agent framework | C30: Framework v1.0: full build-and-test lifecycle | D30: Add architecture, security (merge the security team's agent) and test agents, plus release-manifest and incident-to-intent skills; feedback loop from mistakes to known traps and eval cases. | E30: v1.0 released; at least 15 eval cases passing at 85% or better. | F30: Not in sdlc-core yet: architecture and security reviewer agents, release manifest, incident-to-intent. Drafts are in docs/adoption/starter-kit. | G30: Not started | H30: Green | I30: 46356 | J30: 46374 | K30: Framework engineers (TF) | L30: Security champion. | M30: 4.4 | N30: Stage 5 | O30: Company plan: agents from December.
A31: 4.6 | B31: 4. Agent framework | C31: Agent eval suite in CI | D31: Seed cases from historical PRs (playbook E1); run on every framework change and weekly; publish the pass rate. | E31: 15 cases by Fri 18 Dec; 30 by Fri 26 Feb 2027; pass rate of at least 85% enforced. | F31: sdlc-core has 5 plugin-eval cases with a baseline arm (make evals); the starter kit adds a claude -p harness and EVAL-0001. | G31: Not started | H31: Green | I31: 46349 | J31: 46444 | K31: Framework engineers (TF) | M31: 4.2 | N31: Stage 5
A32: 4.7 | B32: 4. Agent framework | C32: Continuous improvement loop | D32: Every repeated agent mistake becomes a known trap and an eval case within 5 working days; weekly framework release notes. | E32: Loop running; repeat-mistake count falls month on month. | F32: Not started. | G32: Not started | H32: Green | I32: 46357 | J32: 46689 | K32: Framework engineers (TF) | M32: 4.5 | N32: Stage 5 | O32: Ongoing.
A33: 4.8 | B33: 4. Agent framework | C33: Operations (SRE) diagnosis agent | D33: Merge the operations team's agent into an Agent SDK service with read-only observability tools; L1–L2 on one service. | E33: Design approved Fri 29 Jan 2027; L1–L2 live on one service by Fri 26 Mar 2027. | F33: An operations agent exists, built separately. | G33: Not started | H33: Green | I33: 46391 | J33: 46472 | K33: Ops/SRE champion (TF) | L33: Observability team; owner of the existing agent. | M33: 4.5 | N33: Stage 5
A34: 5.1 | B34: 5. Agentic SDLC workflow | C34: Pilot readout | D34: Retro with the current pilot team; numbers so far (change lead time, rework); what to keep, change or stop. | E34: Readout presented at the Mon 9 Nov review. | F34: Pilot running in one team. | G34: Not started | H34: Green | I34: 46321 | J34: 46332 | K34: Pilot team lead | L34: Lead facilitates. | N34: Stage 5
A35: 5.2 | B35: 5. Agentic SDLC workflow | C35: Standard workflow v1 with phase gates | D35: Intent, spec, plan, code, test, PR, release evidence; a gate per phase; tiered by change class (trivial, standard, significant, high-risk); templates from the starter kit. | E35: Workflow v1 published and used by the pilot team. | F35: Templates and skills ready in the kit. | G35: Not started | H35: Green | I35: 46328 | J35: 46346 | K35: Amar (lead) | L35: Pilot team. | M35: 5.1 | N35: Stage 5 | O35: Built from the pilot's feedback.
A36: 5.3 | B36: 5. Agentic SDLC workflow | C36: Pilot team reaches autonomy stage 2 | D36: Agent drafts the intent and the PR; a human reviews the PR. Track the share of changes through the workflow every week. | E36: At least 80% of the pilot team's eligible changes through the workflow; change lead time down 30% against baseline. | F36: Today: agent assists, human approves (stage 1). | G36: Not started | H36: Green | I36: 46349 | J36: 46374 | K36: Pilot team lead | L36: Framework v0.5 (4.4). | M36: 4.4, 5.2 | N36: Stage 5
A37: 5.4 | B37: 5. Agentic SDLC workflow | C37: Onboard the 4–5 backend teams | D37: Two cohorts; repo standard first; workflow training with the framework; weekly retro per team. | E37: Cohort 1 live by Fri 29 Jan; cohort 2 by Fri 26 Feb; at least 60% of eligible changes through the workflow by Fri 30 Apr 2027. | F37: Teams not yet named (D7). | G37: Not started | H37: Green | I37: 46391 | J37: 46507 | K37: Amar (lead) | L37: Engineering managers of the backend teams. | M37: 3.3, 5.3 | N37: Stage 5
A38: 5.5 | B38: 5. Agentic SDLC workflow | C38: Automated gates in shadow, then retire human gates | D38: Log the automated decision next to the human one for every PR; retire a human gate for the standard class only after 4 weeks at 90% agreement and no missed blocker. | E38: Shadow log from Mon 1 Feb 2027; first human gate retired for the standard class by Fri 30 Apr 2027. | F38: Not started. | G38: Not started | H38: Green | I38: 46419 | J38: 46507 | K38: Amar (lead) | L38: Executive sponsor decision D10 when the bar is met. | M38: 3.7 | N38: Stage 3
A39: 5.6 | B39: 5. Agentic SDLC workflow | C39: Multi-agent PR review in CI | D39: anthropics/claude-code-action with the code-review plugin and our reviewer agents; findings carry severity, evidence, file:line and policy. | E39: Running on all pilot and cohort repos; human review time per PR down 20%. | F39: Workflow file ready in the kit. | G39: Not started | H39: Green | I39: 46419 | J39: 46444 | K39: Framework engineers (TF) | L39: Repo admins; Claude GitHub App installed. | M39: 4.5 | N39: Stage 5
A40: 5.7 | B40: 5. Agentic SDLC workflow | C40: Release agent up to staging | D40: Build once, deploy to dev, QA and staging with short-lived scoped credentials; release manifest written by the agent; production stays behind a human or policy gate. | E40: Release manifests for 100% of standard changes in onboarded teams. | F40: Not started. | G40: Not started | H40: Green | I40: 46447 | J40: 46472 | K40: Framework engineers (TF) | L40: Platform and release teams. | M40: 5.6, 7.1 | N40: Stage 5
...

Sheet Timeline
A1: Timeline by week
A2: Built from the Plan sheet's dates. Amber marks the finish week. | E2: Oct 26 | F2: Nov 26 | J2: Dec 26 | O2: Jan 27 | S2: Feb 27 | W2: Mar 27 | AA2: Apr 27 | AF2: May 27 | AJ2: Jun 27 | AN2: Jul 27 | AS2: Aug 27 | AW2: Sep 27 | BB2: Oct 27 | BF2: Nov 27
E3: 46321 | F3: =E3+7 -> 46328 | G3: =F3+7 -> 46335 | H3: =G3+7 -> 46342 | I3: =H3+7 -> 46349 | J3: =I3+7 -> 46356 | K3: =J3+7 -> 46363 | L3: =K3+7 -> 46370 | M3: =L3+7 -> 46377 | ... BF3: =BE3+7 -> 46692
A4: ID | B4: Action | C4: Start | D4: Finish | E4: =E3 -> 46321 | F4: =F3 -> 46328 | G4: =G3 -> 46335 | H4: =H3 -> 46342 | I4: =I3 -> 46349 | J4: =J3 -> 46356 | K4: =K3 -> 46363 | L4: =L3 -> 46370 | ... BF4: =BF3 -> 46692
A5: 1.1 | B5: =IFERROR(INDEX(Plan!$C$2:$C$400,MATCH($A5,Plan!$A$2:$A$400,0)),"") -> Review plan v1 at the biweekly review | C5: =IFERROR(INDEX(Plan!$I$2:$I$400,MATCH($A5,Plan!$A$2:$A$400,0)),"") -> 46318 | D5: =IFERROR(INDEX(Plan!$J$2:$J$400,MATCH($A5,Plan!$A$2:$A$400,0)),"") -> 46321 | E5: =IF(OR($C5="",$D5=""),"",IF(AND(E$3<=$D5,E$3+6>=$C5),IF(AND($D5>=E$3,$D5<=E$3+6),2,1),"")) -> 2 | F5: =IF(OR($C5="",$D5=""),"",IF(AND(F$3<=$D5,F$3+6>=$C5),IF(AND($D5>=F$3,$D5<=F$3+6),2,1),"")) | G5: =IF(OR($C5="",$D5=""),"",IF(AND(G$3<=$D5,G$3+6>=$C5),IF(AND($D5>=G$3,$D5<=G$3+6),2,1),"")) | H5: =IF(OR($C5="",$D5=""),"",IF(AND(H$3<=$D5,H$3+6>=$C5),IF(AND($D5>=H$3,$D5<=H$3+6),2,1),"")) | I5: =IF(OR($C5="",$D5=""),"",IF(AND(I$3<=$D5,I$3+6>=$C5),IF(AND($D5>=I$3,$D5<=I$3+6),2,1),"")) | J5: =IF(OR($C5="",$D5=""),"",IF(AND(J$3<=$D5,J$3+6>=$C5),IF(AND($D5>=J$3,$D5<=J$3+6),2,1),"")) | K5: =IF(OR($C5="",$D5=""),"",IF(AND(K$3<=$D5,K$3+6>=$C5),IF(AND($D5>=K$3,$D5<=K$3+6),2,1),"")) | L5: =IF(OR($C5="",$D5=""),"",IF(AND(L$3<=$D5,L$3+6>=$C5),IF(AND($D5>=L$3,$D5<=L$3+6),2,1),"")) | ... BF5: =IF(OR($C5="",$D5=""),"",IF(AND(BF$3<=$D5,BF$3+6>=$C5),IF(AND($D5>=BF$3,$D5<=BF$3+6),2,1),""))
A6: 1.2 | B6: =IFERROR(INDEX(Plan!$C$2:$C$400,MATCH($A6,Plan!$A$2:$A$400,0)),"") -> Form the task force | C6: =IFERROR(INDEX(Plan!$I$2:$I$400,MATCH($A6,Plan!$A$2:$A$400,0)),"") -> 46321 | D6: =IFERROR(INDEX(Plan!$J$2:$J$400,MATCH($A6,Plan!$A$2:$A$400,0)),"") -> 46323 | E6: =IF(OR($C6="",$D6=""),"",IF(AND(E$3<=$D6,E$3+6>=$C6),IF(AND($D6>=E$3,$D6<=E$3+6),2,1),"")) -> 2 | F6: =IF(OR($C6="",$D6=""),"",IF(AND(F$3<=$D6,F$3+6>=$C6),IF(AND($D6>=F$3,$D6<=F$3+6),2,1),"")) | G6: =IF(OR($C6="",$D6=""),"",IF(AND(G$3<=$D6,G$3+6>=$C6),IF(AND($D6>=G$3,$D6<=G$3+6),2,1),"")) | H6: =IF(OR($C6="",$D6=""),"",IF(AND(H$3<=$D6,H$3+6>=$C6),IF(AND($D6>=H$3,$D6<=H$3+6),2,1),"")) | I6: =IF(OR($C6="",$D6=""),"",IF(AND(I$3<=$D6,I$3+6>=$C6),IF(AND($D6>=I$3,$D6<=I$3+6),2,1),"")) | J6: =IF(OR($C6="",$D6=""),"",IF(AND(J$3<=$D6,J$3+6>=$C6),IF(AND($D6>=J$3,$D6<=J$3+6),2,1),"")) | K6: =IF(OR($C6="",$D6=""),"",IF(AND(K$3<=$D6,K$3+6>=$C6),IF(AND($D6>=K$3,$D6<=K$3+6),2,1),"")) | L6: =IF(OR($C6="",$D6=""),"",IF(AND(L$3<=$D6,L$3+6>=$C6),IF(AND($D6>=L$3,$D6<=L$3+6),2,1),"")) | ... BF6: =IF(OR($C6="",$D6=""),"",IF(AND(BF$3<=$D6,BF$3+6>=$C6),IF(AND($D6>=BF$3,$D6<=BF$3+6),2,1),""))
A7: 1.3 | B7: =IFERROR(INDEX(Plan!$C$2:$C$400,MATCH($A7,Plan!$A$2:$A$400,0)),"") -> Kick off the task force | C7: =IFERROR(INDEX(Plan!$I$2:$I$400,MATCH($A7,Plan!$A$2:$A$400,0)),"") -> 46324 | D7: =IFERROR(INDEX(Plan!$J$2:$J$400,MATCH($A7,Plan!$A$2:$A$400,0)),"") -> 46324 | E7: =IF(OR($C7="",$D7=""),"",IF(AND(E$3<=$D7,E$3+6>=$C7),IF(AND($D7>=E$3,$D7<=E$3+6),2,1),"")) -> 2 | F7: =IF(OR($C7="",$D7=""),"",IF(AND(F$3<=$D7,F$3+6>=$C7),IF(AND($D7>=F$3,$D7<=F$3+6),2,1),"")) | G7: =IF(OR($C7="",$D7=""),"",IF(AND(G$3<=$D7,G$3+6>=$C7),IF(AND($D7>=G$3,$D7<=G$3+6),2,1),"")) | H7: =IF(OR($C7="",$D7=""),"",IF(AND(H$3<=$D7,H$3+6>=$C7),IF(AND($D7>=H$3,$D7<=H$3+6),2,1),"")) | I7: =IF(OR($C7="",$D7=""),"",IF(AND(I$3<=$D7,I$3+6>=$C7),IF(AND($D7>=I$3,$D7<=I$3+6),2,1),"")) | J7: =IF(OR($C7="",$D7=""),"",IF(AND(J$3<=$D7,J$3+6>=$C7),IF(AND($D7>=J$3,$D7<=J$3+6),2,1),"")) | K7: =IF(OR($C7="",$D7=""),"",IF(AND(K$3<=$D7,K$3+6>=$C7),IF(AND($D7>=K$3,$D7<=K$3+6),2,1),"")) | L7: =IF(OR($C7="",$D7=""),"",IF(AND(L$3<=$D7,L$3+6>=$C7),IF(AND($D7>=L$3,$D7<=L$3+6),2,1),"")) | ... BF7: =IF(OR($C7="",$D7=""),"",IF(AND(BF$3<=$D7,BF$3+6>=$C7),IF(AND($D7>=BF$3,$D7<=BF$3+6),2,1),""))
A8: 1.4 | B8: =IFERROR(INDEX(Plan!$C$2:$C$400,MATCH($A8,Plan!$A$2:$A$400,0)),"") -> Run the program cadence | C8: =IFERROR(INDEX(Plan!$I$2:$I$400,MATCH($A8,Plan!$A$2:$A$400,0)),"") -> 46324 | D8: =IFERROR(INDEX(Plan!$J$2:$J$400,MATCH($A8,Plan!$A$2:$A$400,0)),"") -> 46689 | E8: =IF(OR($C8="",$D8=""),"",IF(AND(E$3<=$D8,E$3+6>=$C8),IF(AND($D8>=E$3,$D8<=E$3+6),2,1),"")) -> 1 | F8: =IF(OR($C8="",$D8=""),"",IF(AND(F$3<=$D8,F$3+6>=$C8),IF(AND($D8>=F$3,$D8<=F$3+6),2,1),"")) -> 1 | G8: =IF(OR($C8="",$D8=""),"",IF(AND(G$3<=$D8,G$3+6>=$C8),IF(AND($D8>=G$3,$D8<=G$3+6),2,1),"")) -> 1 | H8: =IF(OR($C8="",$D8=""),"",IF(AND(H$3<=$D8,H$3+6>=$C8),IF(AND($D8>=H$3,$D8<=H$3+6),2,1),"")) -> 1 | I8: =IF(OR($C8="",$D8=""),"",IF(AND(I$3<=$D8,I$3+6>=$C8),IF(AND($D8>=I$3,$D8<=I$3+6),2,1),"")) -> 1 | J8: =IF(OR($C8="",$D8=""),"",IF(AND(J$3<=$D8,J$3+6>=$C8),IF(AND($D8>=J$3,$D8<=J$3+6),2,1),"")) -> 1 | K8: =IF(OR($C8="",$D8=""),"",IF(AND(K$3<=$D8,K$3+6>=$C8),IF(AND($D8>=K$3,$D8<=K$3+6),2,1),"")) -> 1 | L8: =IF(OR($C8="",$D8=""),"",IF(AND(L$3<=$D8,L$3+6>=$C8),IF(AND($D8>=L$3,$D8<=L$3+6),2,1),"")) -> 1 | ... BF8: =IF(OR($C8="",$D8=""),"",IF(AND(BF$3<=$D8,BF$3+6>=$C8),IF(AND($D8>=BF$3,$D8<=BF$3+6),2,1),""))
A9: 1.5 | B9: =IFERROR(INDEX(Plan!$C$2:$C$400,MATCH($A9,Plan!$A$2:$A$400,0)),"") -> Inventory and consolidate existing agent efforts | C9: =IFERROR(INDEX(Plan!$I$2:$I$400,MATCH($A9,Plan!$A$2:$A$400,0)),"") -> 46321 | D9: =IFERROR(INDEX(Plan!$J$2:$J$400,MATCH($A9,Plan!$A$2:$A$400,0)),"") -> 46332 | E9: =IF(OR($C9="",$D9=""),"",IF(AND(E$3<=$D9,E$3+6>=$C9),IF(AND($D9>=E$3,$D9<=E$3+6),2,1),"")) -> 1 | F9: =IF(OR($C9="",$D9=""),"",IF(AND(F$3<=$D9,F$3+6>=$C9),IF(AND($D9>=F$3,$D9<=F$3+6),2,1),"")) -> 2 | G9: =IF(OR($C9="",$D9=""),"",IF(AND(G$3<=$D9,G$3+6>=$C9),IF(AND($D9>=G$3,$D9<=G$3+6),2,1),"")) | H9: =IF(OR($C9="",$D9=""),"",IF(AND(H$3<=$D9,H$3+6>=$C9),IF(AND($D9>=H$3,$D9<=H$3+6),2,1),"")) | I9: =IF(OR($C9="",$D9=""),"",IF(AND(I$3<=$D9,I$3+6>=$C9),IF(AND($D9>=I$3,$D9<=I$3+6),2,1),"")) | J9: =IF(OR($C9="",$D9=""),"",IF(AND(J$3<=$D9,J$3+6>=$C9),IF(AND($D9>=J$3,$D9<=J$3+6),2,1),"")) | K9: =IF(OR($C9="",$D9=""),"",IF(AND(K$3<=$D9,K$3+6>=$C9),IF(AND($D9>=K$3,$D9<=K$3+6),2,1),"")) | L9: =IF(OR($C9="",$D9=""),"",IF(AND(L$3<=$D9,L$3+6>=$C9),IF(AND($D9>=L$3,$D9<=L$3+6),2,1),"")) | ... BF9: =IF(OR($C9="",$D9=""),"",IF(AND(BF$3<=$D9,BF$3+6>=$C9),IF(AND($D9>=BF$3,$D9<=BF$3+6),2,1),""))
A10: 1.6 | B10: =IFERROR(INDEX(Plan!$C$2:$C$400,MATCH($A10,Plan!$A$2:$A$400,0)),"") -> Lead focus and working arrangement | C10: =IFERROR(INDEX(Plan!$I$2:$I$400,MATCH($A10,Plan!$A$2:$A$400,0)),"") -> 46321 | D10: =IFERROR(INDEX(Plan!$J$2:$J$400,MATCH($A10,Plan!$A$2:$A$400,0)),"") -> 46325 | E10: =IF(OR($C10="",$D10=""),"",IF(AND(E$3<=$D10,E$3+6>=$C10),IF(AND($D10>=E$3,$D10<=E$3+6),2,1),"")) -> 2 | F10: =IF(OR($C10="",$D10=""),"",IF(AND(F$3<=$D10,F$3+6>=$C10),IF(AND($D10>=F$3,$D10<=F$3+6),2,1),"")) | G10: =IF(OR($C10="",$D10=""),"",IF(AND(G$3<=$D10,G$3+6>=$C10),IF(AND($D10>=G$3,$D10<=G$3+6),2,1),"")) | H10: =IF(OR($C10="",$D10=""),"",IF(AND(H$3<=$D10,H$3+6>=$C10),IF(AND($D10>=H$3,$D10<=H$3+6),2,1),"")) | I10: =IF(OR($C10="",$D10=""),"",IF(AND(I$3<=$D10,I$3+6>=$C10),IF(AND($D10>=I$3,$D10<=I$3+6),2,1),"")) | J10: =IF(OR($C10="",$D10=""),"",IF(AND(J$3<=$D10,J$3+6>=$C10),IF(AND($D10>=J$3,$D10<=J$3+6),2,1),"")) | K10: =IF(OR($C10="",$D10=""),"",IF(AND(K$3<=$D10,K$3+6>=$C10),IF(AND($D10>=K$3,$D10<=K$3+6),2,1),"")) | L10: =IF(OR($C10="",$D10=""),"",IF(AND(L$3<=$D10,L$3+6>=$C10),IF(AND($D10>=L$3,$D10<=L$3+6),2,1),"")) | ... BF10: =IF(OR($C10="",$D10=""),"",IF(AND(BF$3<=$D10,BF$3+6>=$C10),IF(AND($D10>=BF$3,$D10<=BF$3+6),2,1),""))
A11: 1.7 | B11: =IFERROR(INDEX(Plan!$C$2:$C$400,MATCH($A11,Plan!$A$2:$A$400,0)),"") -> Industry evidence pack | C11: =IFERROR(INDEX(Plan!$I$2:$I$400,MATCH($A11,Plan!$A$2:$A$400,0)),"") -> 46321 | D11: =IFERROR(INDEX(Plan!$J$2:$J$400,MATCH($A11,Plan!$A$2:$A$400,0)),"") -> 46332 | E11: =IF(OR($C11="",$D11=""),"",IF(AND(E$3<=$D11,E$3+6>=$C11),IF(AND($D11>=E$3,$D11<=E$3+6),2,1),"")) -> 1 | F11: =IF(OR($C11="",$D11=""),"",IF(AND(F$3<=$D11,F$3+6>=$C11),IF(AND($D11>=F$3,$D11<=F$3+6),2,1),"")) -> 2 | G11: =IF(OR($C11="",$D11=""),"",IF(AND(G$3<=$D11,G$3+6>=$C11),IF(AND($D11>=G$3,$D11<=G$3+6),2,1),"")) | H11: =IF(OR($C11="",$D11=""),"",IF(AND(H$3<=$D11,H$3+6>=$C11),IF(AND($D11>=H$3,$D11<=H$3+6),2,1),"")) | I11: =IF(OR($C11="",$D11=""),"",IF(AND(I$3<=$D11,I$3+6>=$C11),IF(AND($D11>=I$3,$D11<=I$3+6),2,1),"")) | J11: =IF(OR($C11="",$D11=""),"",IF(AND(J$3<=$D11,J$3+6>=$C11),IF(AND($D11>=J$3,$D11<=J$3+6),2,1),"")) | K11: =IF(OR($C11="",$D11=""),"",IF(AND(K$3<=$D11,K$3+6>=$C11),IF(AND($D11>=K$3,$D11<=K$3+6),2,1),"")) | L11: =IF(OR($C11="",$D11=""),"",IF(AND(L$3<=$D11,L$3+6>=$C11),IF(AND($D11>=L$3,$D11<=L$3+6),2,1),"")) | ... BF11: =IF(OR($C11="",$D11=""),"",IF(AND(BF$3<=$D11,BF$3+6>=$C11),IF(AND($D11>=BF$3,$D11<=BF$3+6),2,1),""))
A12: 1.8 | B12: =IFERROR(INDEX(Plan!$C$2:$C$400,MATCH($A12,Plan!$A$2:$A$400,0)),"") -> Align the strategy document | C12: =IFERROR(INDEX(Plan!$I$2:$I$400,MATCH($A12,Plan!$A$2:$A$400,0)),"") -> 46321 | D12: =IFERROR(INDEX(Plan!$J$2:$J$400,MATCH($A12,Plan!$A$2:$A$400,0)),"") -> 46323 | E12: =IF(OR($C12="",$D12=""),"",IF(AND(E$3<=$D12,E$3+6>=$C12),IF(AND($D12>=E$3,$D12<=E$3+6),2,1),"")) -> 2 | F12: =IF(OR($C12="",$D12=""),"",IF(AND(F$3<=$D12,F$3+6>=$C12),IF(AND($D12>=F$3,$D12<=F$3+6),2,1),"")) | G12: =IF(OR($C12="",$D12=""),"",IF(AND(G$3<=$D12,G$3+6>=$C12),IF(AND($D12>=G$3,$D12<=G$3+6),2,1),"")) | H12: =IF(OR($C12="",$D12=""),"",IF(AND(H$3<=$D12,H$3+6>=$C12),IF(AND($D12>=H$3,$D12<=H$3+6),2,1),"")) | I12: =IF(OR($C12="",$D12=""),"",IF(AND(I$3<=$D12,I$3+6>=$C12),IF(AND($D12>=I$3,$D12<=I$3+6),2,1),"")) | J12: =IF(OR($C12="",$D12=""),"",IF(AND(J$3<=$D12,J$3+6>=$C12),IF(AND($D12>=J$3,$D12<=J$3+6),2,1),"")) | K12: =IF(OR($C12="",$D12=""),"",IF(AND(K$3<=$D12,K$3+6>=$C12),IF(AND($D12>=K$3,$D12<=K$3+6),2,1),"")) | L12: =IF(OR($C12="",$D12=""),"",IF(AND(L$3<=$D12,L$3+6>=$C12),IF(AND($D12>=L$3,$D12<=L$3+6),2,1),"")) | ... BF12: =IF(OR($C12="",$D12=""),"",IF(AND(BF$3<=$D12,BF$3+6>=$C12),IF(AND($D12>=BF$3,$D12<=BF$3+6),2,1),""))
A13: 1.9 | B13: =IFERROR(INDEX(Plan!$C$2:$C$400,MATCH($A13,Plan!$A$2:$A$400,0)),"") -> Engineering-wide communication | C13: =IFERROR(INDEX(Plan!$I$2:$I$400,MATCH($A13,Plan!$A$2:$A$400,0)),"") -> 46328 | D13: =IFERROR(INDEX(Plan!$J$2:$J$400,MATCH($A13,Plan!$A$2:$A$400,0)),"") -> 46374 | E13: =IF(OR($C13="",$D13=""),"",IF(AND(E$3<=$D13,E$3+6>=$C13),IF(AND($D13>=E$3,$D13<=E$3+6),2,1),"")) | F13: =IF(OR($C13="",$D13=""),"",IF(AND(F$3<=$D13,F$3+6>=$C13),IF(AND($D13>=F$3,$D13<=F$3+6),2,1),"")) -> 1 | G13: =IF(OR($C13="",$D13=""),"",IF(AND(G$3<=$D13,G$3+6>=$C13),IF(AND($D13>=G$3,$D13<=G$3+6),2,1),"")) -> 1 | H13: =IF(OR($C13="",$D13=""),"",IF(AND(H$3<=$D13,H$3+6>=$C13),IF(AND($D13>=H$3,$D13<=H$3+6),2,1),"")) -> 1 | I13: =IF(OR($C13="",$D13=""),"",IF(AND(I$3<=$D13,I$3+6>=$C13),IF(AND($D13>=I$3,$D13<=I$3+6),2,1),"")) -> 1 | J13: =IF(OR($C13="",$D13=""),"",IF(AND(J$3<=$D13,J$3+6>=$C13),IF(AND($D13>=J$3,$D13<=J$3+6),2,1),"")) -> 1 | K13: =IF(OR($C13="",$D13=""),"",IF(AND(K$3<=$D13,K$3+6>=$C13),IF(AND($D13>=K$3,$D13<=K$3+6),2,1),"")) -> 1 | L13: =IF(OR($C13="",$D13=""),"",IF(AND(L$3<=$D13,L$3+6>=$C13),IF(AND($D13>=L$3,$D13<=L$3+6),2,1),"")) -> 2 | ... BF13: =IF(OR($C13="",$D13=""),"",IF(AND(BF$3<=$D13,BF$3+6>=$C13),IF(AND($D13>=BF$3,$D13<=BF$3+6),2,1),""))
A14: 2.1 | B14: =IFERROR(INDEX(Plan!$C$2:$C$400,MATCH($A14,Plan!$A$2:$A$400,0)),"") -> Lock the baseline from internal analytics | C14: =IFERROR(INDEX(Plan!$I$2:$I$400,MATCH($A14,Plan!$A$2:$A$400,0)),"") -> 46321 | D14: =IFERROR(INDEX(Plan!$J$2:$J$400,MATCH($A14,Plan!$A$2:$A$400,0)),"") -> 46332 | E14: =IF(OR($C14="",$D14=""),"",IF(AND(E$3<=$D14,E$3+6>=$C14),IF(AND($D14>=E$3,$D14<=E$3+6),2,1),"")) -> 1 | F14: =IF(OR($C14="",$D14=""),"",IF(AND(F$3<=$D14,F$3+6>=$C14),IF(AND($D14>=F$3,$D14<=F$3+6),2,1),"")) -> 2 | G14: =IF(OR($C14="",$D14=""),"",IF(AND(G$3<=$D14,G$3+6>=$C14),IF(AND($D14>=G$3,$D14<=G$3+6),2,1),"")) | H14: =IF(OR($C14="",$D14=""),"",IF(AND(H$3<=$D14,H$3+6>=$C14),IF(AND($D14>=H$3,$D14<=H$3+6),2,1),"")) | I14: =IF(OR($C14="",$D14=""),"",IF(AND(I$3<=$D14,I$3+6>=$C14),IF(AND($D14>=I$3,$D14<=I$3+6),2,1),"")) | J14: =IF(OR($C14="",$D14=""),"",IF(AND(J$3<=$D14,J$3+6>=$C14),IF(AND($D14>=J$3,$D14<=J$3+6),2,1),"")) | K14: =IF(OR($C14="",$D14=""),"",IF(AND(K$3<=$D14,K$3+6>=$C14),IF(AND($D14>=K$3,$D14<=K$3+6),2,1),"")) | L14: =IF(OR($C14="",$D14=""),"",IF(AND(L$3<=$D14,L$3+6>=$C14),IF(AND($D14>=L$3,$D14<=L$3+6),2,1),"")) | ... BF14: =IF(OR($C14="",$D14=""),"",IF(AND(BF$3<=$D14,BF$3+6>=$C14),IF(AND($D14>=BF$3,$D14<=BF$3+6),2,1),""))
A15: 2.2 | B15: =IFERROR(INDEX(Plan!$C$2:$C$400,MATCH($A15,Plan!$A$2:$A$400,0)),"") -> Measure AI code share in production | C15: =IFERROR(INDEX(Plan!$I$2:$I$400,MATCH($A15,Plan!$A$2:$A$400,0)),"") -> 46328 | D15: =IFERROR(INDEX(Plan!$J$2:$J$400,MATCH($A15,Plan!$A$2:$A$400,0)),"") -> 46346 | E15: =IF(OR($C15="",$D15=""),"",IF(AND(E$3<=$D15,E$3+6>=$C15),IF(AND($D15>=E$3,$D15<=E$3+6),2,1),"")) | F15: =IF(OR($C15="",$D15=""),"",IF(AND(F$3<=$D15,F$3+6>=$C15),IF(AND($D15>=F$3,$D15<=F$3+6),2,1),"")) -> 1 | G15: =IF(OR($C15="",$D15=""),"",IF(AND(G$3<=$D15,G$3+6>=$C15),IF(AND($D15>=G$3,$D15<=G$3+6),2,1),"")) -> 1 | H15: =IF(OR($C15="",$D15=""),"",IF(AND(H$3<=$D15,H$3+6>=$C15),IF(AND($D15>=H$3,$D15<=H$3+6),2,1),"")) -> 2 | I15: =IF(OR($C15="",$D15=""),"",IF(AND(I$3<=$D15,I$3+6>=$C15),IF(AND($D15>=I$3,$D15<=I$3+6),2,1),"")) | J15: =IF(OR($C15="",$D15=""),"",IF(AND(J$3<=$D15,J$3+6>=$C15),IF(AND($D15>=J$3,$D15<=J$3+6),2,1),"")) | K15: =IF(OR($C15="",$D15=""),"",IF(AND(K$3<=$D15,K$3+6>=$C15),IF(AND($D15>=K$3,$D15<=K$3+6),2,1),"")) | L15: =IF(OR($C15="",$D15=""),"",IF(AND(L$3<=$D15,L$3+6>=$C15),IF(AND($D15>=L$3,$D15<=L$3+6),2,1),"")) | ... BF15: =IF(OR($C15="",$D15=""),"",IF(AND(BF$3<=$D15,BF$3+6>=$C15),IF(AND($D15>=BF$3,$D15<=BF$3+6),2,1),""))
A16: 2.3 | B16: =IFERROR(INDEX(Plan!$C$2:$C$400,MATCH($A16,Plan!$A$2:$A$400,0)),"") -> Feature-level flow records for the pilot team | C16: =IFERROR(INDEX(Plan!$I$2:$I$400,MATCH($A16,Plan!$A$2:$A$400,0)),"") -> 46328 | D16: =IFERROR(INDEX(Plan!$J$2:$J$400,MATCH($A16,Plan!$A$2:$A$400,0)),"") -> 46353 | E16: =IF(OR($C16="",$D16=""),"",IF(AND(E$3<=$D16,E$3+6>=$C16),IF(AND($D16>=E$3,$D16<=E$3+6),2,1),"")) | F16: =IF(OR($C16="",$D16=""),"",IF(AND(F$3<=$D16,F$3+6>=$C16),IF(AND($D16>=F$3,$D16<=F$3+6),2,1),"")) -> 1 | G16: =IF(OR($C16="",$D16=""),"",IF(AND(G$3<=$D16,G$3+6>=$C16),IF(AND($D16>=G$3,$D16<=G$3+6),2,1),"")) -> 1 | H16: =IF(OR($C16="",$D16=""),"",IF(AND(H$3<=$D16,H$3+6>=$C16),IF(AND($D16>=H$3,$D16<=H$3+6),2,1),"")) -> 1 | I16: =IF(OR($C16="",$D16=""),"",IF(AND(I$3<=$D16,I$3+6>=$C16),IF(AND($D16>=I$3,$D16<=I$3+6),2,1),"")) -> 2 | J16: =IF(OR($C16="",$D16=""),"",IF(AND(J$3<=$D16,J$3+6>=$C16),IF(AND($D16>=J$3,$D16<=J$3+6),2,1),"")) | K16: =IF(OR($C16="",$D16=""),"",IF(AND(K$3<=$D16,K$3+6>=$C16),IF(AND($D16>=K$3,$D16<=K$3+6),2,1),"")) | L16: =IF(OR($C16="",$D16=""),"",IF(AND(L$3<=$D16,L$3+6>=$C16),IF(AND($D16>=L$3,$D16<=L$3+6),2,1),"")) | ... BF16: =IF(OR($C16="",$D16=""),"",IF(AND(BF$3<=$D16,BF$3+6>=$C16),IF(AND($D16>=BF$3,$D16<=BF$3+6),2,1),""))
... A58: 8.4 | B58: =IFERROR(INDEX(Plan!$C$2:$C$400,MATCH($A58,Plan!$A$2:$A$400,0)),"") -> 12-month readout and year-two plan | C58: =IFERROR(INDEX(Plan!$I$2:$I$400,MATCH($A58,Plan!$A$2:$A$400,0)),"") -> 46678 | D58: =IFERROR(INDEX(Plan!$J$2:$J$400,MATCH($A58,Plan!$A$2:$A$400,0)),"") -> 46692 | E58: =IF(OR($C58="",$D58=""),"",IF(AND(E$3<=$D58,E$3+6>=$C58),IF(AND($D58>=E$3,$D58<=E$3+6),2,1),"")) | F58: =IF(OR($C58="",$D58=""),"",IF(AND(F$3<=$D58,F$3+6>=$C58),IF(AND($D58>=F$3,$D58<=F$3+6),2,1),"")) | G58: =IF(OR($C58="",$D58=""),"",IF(AND(G$3<=$D58,G$3+6>=$C58),IF(AND($D58>=G$3,$D58<=G$3+6),2,1),"")) | H58: =IF(OR($C58="",$D58=""),"",IF(AND(H$3<=$D58,H$3+6>=$C58),IF(AND($D58>=H$3,$D58<=H$3+6),2,1),"")) | I58: =IF(OR($C58="",$D58=""),"",IF(AND(I$3<=$D58,I$3+6>=$C58),IF(AND($D58>=I$3,$D58<=I$3+6),2,1),"")) | J58: =IF(OR($C58="",$D58=""),"",IF(AND(J$3<=$D58,J$3+6>=$C58),IF(AND($D58>=J$3,$D58<=J$3+6),2,1),"")) | K58: =IF(OR($C58="",$D58=""),"",IF(AND(K$3<=$D58,K$3+6>=$C58),IF(AND($D58>=K$3,$D58<=K$3+6),2,1),"")) | L58: =IF(OR($C58="",$D58=""),"",IF(AND(L$3<=$D58,L$3+6>=$C58),IF(AND($D58>=L$3,$D58<=L$3+6),2,1),"")) | ... BF58: =IF(OR($C58="",$D58=""),"",IF(AND(BF$3<=$D58,BF$3+6>=$C58),IF(AND($D58>=BF$3,$D58<=BF$3+6),2,1),"")) -> 2
B60: Teal: action in progress that week. Amber: planned finish week. Amber header: the current week.

Sheet KPIs
A1: KPIs: baselines and targets
A2: Blue cells are targets you can change. Yellow cells are baselines to fill from internal analytics (action 2.1). Black cells are formulas.
A4: Absolute targets
A5: KPI | B5: Definition | C5: Source | D5: Unit | E5: Better when | F5: Baseline (Oct 2026) | G5: Mon 30 Nov 2026 | H5: Fri 29 Jan 2027 | I5: Fri 30 Apr 2027 | J5: Fri 29 Oct 2027 | K5: Owner | L5: Target status / note
A6: Repos meeting the standard (of 48) | B6: Repos green on the scorecard: CLAUDE.md, rules, make targets, guardrails. | C6: Repo scorecard (3.2) | D6: repos | E6: Higher | F6: 27 | G6: 40 | H6: 48 | I6: 48 | J6: 48 | K6: Standardization squad (TF) | L6: From the company plan.
A7: Critical repos with guardrails | B7: Share of critical repos with guard hooks, deny rules, frozen tests and CODEOWNERS. | C7: Repo scorecard | D7: % | E7: Higher | G7: 0.5 | H7: 1 | I7: 1 | J7: 1 | K7: Standardization squad (TF) | L7: Proposed.
A8: Pilot team: eligible changes through the workflow | B8: Non-trivial changes that followed the artifact chain for their class. | C8: Feature records (2.3) | D8: % | E8: Higher | G8: 0.5 | H8: 0.8 | I8: 0.9 | J8: 0.9 | K8: Pilot team lead | L8: Proposed.
A9: Backend teams: eligible changes through the workflow | B9: Same measure for the 4–5 onboarded backend teams. | C9: Feature records (2.4) | D9: % | E9: Higher | H9: 0.3 | I9: 0.6 | J9: 0.8 | K9: Amar (lead) | L9: Proposed.
A10: Builders on the standard workflow | B10: Builders with at least one change through the workflow in the month. | C10: Feature records | D10: % | E10: Higher | G10: 0.1 | H10: 0.3 | I10: 0.5 | J10: 0.8 | K10: Amar (lead) | L10: Company plan mentions 80%; confirm.
A11: Feature-level record coverage | B11: Share of features with a complete record. | C11: Feature records | D11: % | E11: Higher | F11: 0 | G11: 0.15 | H11: 0.4 | I11: 1 | J11: 1 | K11: Measurement analyst (TF) | L11: Proposed.
A12: Agent eval pass rate | B12: Passed runs ÷ total runs on the eval suite. | C12: evals/results | D12: % | E12: Higher | H12: 0.85 | I12: 0.9 | J12: 0.9 | K12: Framework engineers (TF) | L12: Proposed.
A13: Agent eval cases | B13: Cases in the suite that pass --self-test. | C13: evals/cases | D13: cases | E13: Higher | F13: 1 | G13: 5 | H13: 20 | I13: 30 | J13: 60 | K13: Framework engineers (TF) | L13: Proposed. Baseline: EVAL-0001 in the starter kit.
A14: Conversion-to-control rate | B14: Recurring failures converted into a rule, test, hook or eval ÷ recurring failures reviewed. | C14: Monthly failure review (7.3) | D14: % | E14: Higher | H14: 0.5 | I14: 0.8 | J14: 0.9 | K14: Ops/SRE champion (TF) | L14: Proposed.
A15: Agent sessions with production credentials | B15: Count found in the access review. | C15: Access review (7.1) | D15: sessions | E15: Lower | G15: 0 | H15: 0 | I15: 0 | J15: 0 | K15: Security champion (TF) | L15: Hard rule.
A16: Repos in scope | F16: 48
A17: Repos meeting the standard, share of repos in scope | F17: =IF(F6="","",F6/$F$16) -> 0.5625 | G17: =IF(G6="","",G6/$F$16) -> 0.83333333 | H17: =IF(H6="","",H6/$F$16) -> 1 | I17: =IF(I6="","",I6/$F$16) -> 1 | J17: =IF(J6="","",J6/$F$16) -> 1
A19: Relative targets: change against the baseline
A20: Target = baseline × (1 + change) for relative KPIs, or baseline + change for points and multiples. Change inputs are in columns M–P. Fill the yellow baselines and the targets appear.
A21: KPI | B21: Definition | C21: Source | D21: Unit | E21: Method | F21: Baseline (Oct 2026) | G21: Target 30 Nov 2026 | H21: Target 29 Jan 2027 | I21: Target 30 Apr 2027 | J21: Target 29 Oct 2027 | K21: Owner | L21: Target status / note | M21: Change by 30 Nov | N21: Change by 29 Jan | O21: Change by 30 Apr | P21: Change by 29 Oct 27
A22: AI code share in production | B22: Lines in AI-authored commits merged to main ÷ all merged lines. | C22: AI code share dashboard (2.2) | D22: % | E22: points | G22: =IF($F22="","",MIN(1,$F22+M22/100)) | H22: =IF($F22="","",MIN(1,$F22+N22/100)) | I22: =IF($F22="","",MIN(1,$F22+O22/100)) | J22: =IF($F22="","",MIN(1,$F22+P22/100)) | K22: Measurement analyst (TF) | L22: Company's top metric. Proposed targets. | M22: 0 | N22: 10 | O22: 20 | P22: 30
A23: Change lead time, requirement to PR (pilot team) | B23: Median days from approved intent to PR opened. | C23: Feature records | D23: days | E23: relative | G23: =IF($F23="","",$F23*(1+M23)) | H23: =IF($F23="","",$F23*(1+N23)) | I23: =IF($F23="","",$F23*(1+O23)) | J23: =IF($F23="","",$F23*(1+P23)) | K23: Pilot team lead | L23: Proposed. | M23: -0.15 | N23: -0.3 | O23: -0.5 | P23: -0.6
A24: Feature lead time, request to production | B24: Median days from request received to production (replaces pod-level epic lead time). | C24: Feature records | D24: days | E24: relative | G24: =IF($F24="","",$F24*(1+M24)) | H24: =IF($F24="","",$F24*(1+N24)) | I24: =IF($F24="","",$F24*(1+O24)) | J24: =IF($F24="","",$F24*(1+P24)) | K24: Measurement analyst (TF) | L24: Proposed. | M24: 0 | N24: -0.1 | O24: -0.25 | P24: -0.4
A25: Human review time per PR | B25: Median reviewer hours per PR. | C25: GitHub review events | D25: hours | E25: relative | G25: =IF($F25="","",$F25*(1+M25)) | H25: =IF($F25="","",$F25*(1+N25)) | I25: =IF($F25="","",$F25*(1+O25)) | J25: =IF($F25="","",$F25*(1+P25)) | K25: Amar (lead) | L25: Proposed. | M25: 0 | N25: -0.2 | O25: -0.35 | P25: -0.5
A26: First-pass PR success | B26: Share of PRs with green CI on the first push. | C26: CI | D26: % | E26: points | G26: =IF($F26="","",MIN(1,$F26+M26/100)) | H26: =IF($F26="","",MIN(1,$F26+N26/100)) | I26: =IF($F26="","",MIN(1,$F26+O26/100)) | J26: =IF($F26="","",MIN(1,$F26+P26/100)) | K26: Standardization squad (TF) | L26: Proposed. | M26: 0 | N26: 5 | O26: 10 | P26: 15
A27: Escaped defects per month | B27: Defects traced to a change within 30 days. | C27: Tracker links | D27: defects | E27: relative | G27: =IF($F27="","",$F27*(1+M27)) | H27: =IF($F27="","",$F27*(1+N27)) | I27: =IF($F27="","",$F27*(1+O27)) | J27: =IF($F27="","",$F27*(1+P27)) | K27: Ops/SRE champion (TF) | L27: No worse than baseline while speed rises. | M27: 0 | N27: 0 | O27: -0.1 | P27: -0.25
A28: Repeat preventable failures per quarter | B28: Incidents or failures with a known earlier cause. | C28: Monthly failure review | D28: count | E28: relative | G28: =IF($F28="","",$F28*(1+M28)) | H28: =IF($F28="","",$F28*(1+N28)) | I28: =IF($F28="","",$F28*(1+O28)) | J28: =IF($F28="","",$F28*(1+P28)) | K28: Ops/SRE champion (TF) | L28: Proposed. | M28: 0 | N28: 0 | O28: -0.15 | P28: -0.3
A29: Productivity multiple (company measure) | B29: As defined in the strategy document. | C29: Strategy document | D29: x | E29: points | F29: 1.3 | G29: =IF($F29="","",$F29+M29) -> 1.3 | H29: =IF($F29="","",$F29+N29) -> 1.5 | I29: =IF($F29="","",$F29+O29) -> 2 | J29: =IF($F29="","",$F29+P29) -> 3 | K29: Amar (lead) | L29: Baseline 1.3x from the strategy document; aspiration 10x. Targets proposed for onboarded teams. | M29: 0 | N29: 0.2 | O29: 0.7 | P29: 1.7

Sheet Milestones
A1: Milestones and autonomy stages
A2: Gate reviews fall on the biweekly review after each wave ends.
A4: Date | B4: Milestone | C4: Measure | D4: Wave | E4: Owner
A5: 46321 | B5: Plan v1 reviewed with the executive sponsor | C5: Decisions D1–D5 taken | D5: W0 Mobilize | E5: Amar (lead)
A6: 46323 | B6: Task force approved | C6: 6–7 named members, at least 50% allocated | D6: W0 Mobilize | E6: Program sponsor
A7: 46324 | B7: Task force kickoff | C7: Every member owns at least one action | D7: W0 Mobilize | E7: Amar (lead)
A8: 46332 | B8: Baseline locked; standard v2; framework charter; pilot readout | C8: KPIs sheet baselines filled; charter ready for D4 | D8: W0 Mobilize | E8: Amar (lead)
A9: 46335 | B9: Gate review W0 | C9: Charter approved; evidence pack presented | D9: W0 Mobilize | E9: Executive sponsor
A10: 46346 | B10: AI code share dashboard; plugin marketplace; UI spike | C10: Dashboard live; one-command install; spike demo ready | D10: W1 Standardize and instrument | E10: Measurement analyst (TF)
A11: 46353 | B11: Framework v0.5 in daily use by the pilot team | C11: Pilot team uses intent, planning and verifier agents | D11: W1 Standardize and instrument | E11: Framework engineers (TF)
A12: 46356 | B12: 40 of 48 repos meet the standard | C12: Scorecard | D12: W1 Standardize and instrument | E12: Standardization squad (TF)
A13: 46363 | B13: Gate review W1 | C13: 40/48; telemetry; access review signed off | D13: W1 Standardize and instrument | E13: Executive sponsor
A14: 46374 | B14: Framework v1.0; pilot team at autonomy stage 2; first showcase | C14: 15 eval cases at 85%+; 80% of pilot changes through the workflow | D14: W2 Framework v1 and expansion | E14: Framework engineers (TF)
A15: 46416 | B15: 48 of 48 repos; backend cohort 1 live; role draft | C15: Scorecard; feature records for 4–5 backend teams | D15: W2 Framework v1 and expansion | E15: Standardization squad (TF)
A16: 46419 | B16: Gate review W2 | C16: Shadow gates start | D16: W2 Framework v1 and expansion | E16: Executive sponsor
... A24: 46692 | B24: 12-month readout and year-two plan | C24: Gap assessment re-rated with evidence | D24: W5 Close the loop | E24: Amar (lead)
A27: Autonomy stages (from the company plan)
A28: Stage | B28: Agent does | C28: Human does | D28: Pilot team | E28: Backend teams (4–5) | F28: All teams
A29: 1 Foundation (today) | B29: Assists with code | C29: Writes intents and plans; approves everything | D29: Today | E29: Today | F29: Today
A30: 2 | B30: Drafts the intent and the PR | C30: Reviews the PR | D30: 46374 | E30: 46444 | F30: 46598
A31: 3 | B31: Self-verifies with evidence | C31: Reviews exceptions | D31: 46507 | E31: 46563 | F31: 46689
A32: 4 | B32: Fixes what production signals find and opens the PR (L3) | C32: Final review | D32: 46626 | E32: Year two | F32: Year two
A33: 5 | B33: Remediates within guardrails (L4 named runbooks only) | C33: Audits | D33: Named runbooks after D11 | E33: Year two | F33: Not in year one
A35: Stage dates are proposals for the Mon 26 Oct review.

Sheet Decisions
A1: Decisions needed from leadership
A2: Bring the open ones to the biweekly review on the date shown.
A4: ID | B4: Decision | C4: Recommendation | D4: Needed by | E4: Decided by | F4: Status | G4: Outcome
A5: D1 | B5: Approve plan v1: targets, dates and way of working | C5: Approve, with changes logged. Keep the company targets (40/48 by 30 Nov, 48/48 by 29 Jan, framework from December). Adopt the artifact chain, tiered by change class, and the repo standard as the way of working. | D5: 46321 | E5: Executive sponsor | F5: Open
A6: D2 | B6: Task force | C6: 6–7 people at least 50% allocated from Mon 2 Nov to Fri 29 Jan, nominated by the engineering people leads (Task force sheet). | D6: 46323 | E6: Executive sponsor with the people leads | F6: Open
A7: D3 | B7: One framework, run like production code | C7: Every agent, skill and automation goes through the shared framework; owners of existing agents join as contributors; no new standalone agents after Fri 6 Nov. Framework changes go through PRs with code owners and must pass the eval suite. | D7: 46321 | E7: Executive sponsor | F7: Open
A8: D4 | B8: Form of the framework | C8: Skills-first, packaged as plugins from an internal marketplace. Add hooks where rules must be enforced, subagents for specialist reviews, MCP connectors for Jira and observability, and headless services (Agent SDK, CI) for event-driven agents. See the Evidence sheet. | D8: 46335 | E8: Executive sponsor | F8: Open
A9: D5 | B9: Lead allocation | C9: Transformation lead fully on the program until Fri 29 Jan 2027; other work paused. | D9: 46321 | E9: Executive sponsor with the program sponsor | F9: Open
A10: D6 | B10: Value metrics | C10: Adopt the AI code share method and feature-level records; report value metrics with paired quality metrics; team level only. | D10: 46335 | E10: Executive sponsor | F10: Open
